Workbook

Sheet Investigation Guide
A1: Practice Case A – Investigation Guide
A2: Work through the tabs in the order listed below, base every conclusion on the evidence in this workbook, and record your work where each step tells you to.
A4: INVESTIGATION OBJECTIVE
A5: Review the alerted activity and decide whether it is consistent with what the bank knows about the customer (the KYC profile). Trace the source and the use of the funds - where the money came from and where it went - and quantify what you find. Document a clear, well-supported disposition in 'Disposition & Narrative'. Complete the 'SAR Structured Form' only if your disposition is to file a SAR; if you decide not to file, leave that tab blank.
A7: STEP | B7: TAB | C7: REVIEW FOCUS | D7: ACTION / EXPECTED OUTPUT | E7: NOTE
A8: 1 | B8: Party & Accounts Details | C8: Who the customer is: identity, occupation or business type, expected activity, stated source of funds, the accounts held and any related cases. | D8: Summarise the KYC profile. Note the expected activity you will measure the alerted activity against.
A9: 2 | B9: Accounts | C9: Each account's type, number, owner(s), status, dates and how many alerted events it carries. | D9: Confirm which accounts are in scope and record the account numbers exactly as shown.
A10: 3 | B10: Event Details | C10: The alerted events: monitoring rule, date, account, amount and direction (debits are shown as negative amounts). | D10: List the alerts and find each one on the 'Transactions' tab before you form a view.
A11: 4 | B11: Transactions | C11: All activity on all accounts for the review period: inflows, outflows, counterparties, locations, timing and running balances. | D11: Filter and sort to trace where the money came from and where it went. Use the Group column to tag related rows, and quantify the total of every pattern you rely on. | E11: Use the filters on row 1
A12: 5 | B12: Support_Docs | C12: Supporting documents. | D12: No action needed for this practice case. | E12: Not Required for this case study
A13: 6 | B13: Open_Source_Research | C13: Open-source (internet / media) research. | D13: No action needed for this practice case. | E13: Not Required for this case study
A14: 7 | B14: Disposition & Narrative | C14: Your written conclusion. | D14: Enter your complete narrative in cell A1 of 'Disposition & Narrative' only. Cover who, what, when, where, why the activity is or is not suspicious, the key amounts, accounts and counterparties, the flow of funds, and your final disposition (SAR / No SAR). | E14: Cell A1 only
A15: 8 | B15: SAR Structured Form | C15: FinCEN-style SAR data fields. | D15: If you file, record the filing details here. Mark options by choosing X in the shaded box to the left of each option; type text answers in the shaded boxes. | E15: Complete only if your disposition is to file a SAR
A16: 9 | B16: Case Study Questions | C16: Questions that test how well your findings reconcile to the evidence. | D16: Select one answer per question by entering X in column A. | E16: Complete after steps 7–8
A18: FINAL QUALITY CHECK
A19: Before you submit: (1) reconcile every alerted event on 'Event Details' to its matching row on 'Transactions'; (2) confirm you have considered all relevant inflows and outflows - not only the alerted items - and that every total you quote adds up; (3) make sure your narrative is in cell A1 of 'Disposition & Narrative' and nowhere else; (4) complete the 'SAR Structured Form' only if your disposition supports filing, otherwise leave it blank.

Sheet Party & Accounts Details
A1: Customer Name | B1: Northgate Mobile Repair LLC
A3: CUSTOMER INFORMATION | C3: BANK RELATIONSHIP INFORMATION
A4: Title / Address | B4: 4127 Kessler Commons Blvd, Suite C | C4: Customer Since | D4: 43557
B5: Columbus, OH 43229 | C5: Party ID | D5: 8830215547
B6: United States
A7: TIN/SSN | B7: XX-XXX7316 | C7: CONTACT INFORMATION
A8: Date Established | B8: 43538 | C8: Phone | D8: (614) 555-0147
A9: Business Type / NAICS Description | B9: Cell-phone repair and accessories retail (NAICS 811210 - Electronic and Precision Equipment Repair and Maintenance) | C9: E-mail | D9: northgate.repair@example.com
A10: Owner / Authorized Signer | B10: Desmond J. Bennett - Managing Member, 100% owner, authorized signer
A11: Doing Business As | B11: Northgate Phone Fix
A12: Owner Residential Address | B12: 7720 Saddle Creek Ct, Dublin, OH 43017
A13: Related Personal Account | B13: Personal checking 5523018851447 - Desmond J. Bennett, customer since 2017-08-10
A14: Authorized Depositors (on file) | B14: Desmond J. Bennett (owner); Luis A. Ortega (store manager)
A15: Expected Monthly Activity (2025 KYC refresh) | B15: Card settlements $20,000-$28,000; cash deposits $2,000-$4,000 (night depository); ACH payroll, rent and parts-supplier payments; no international wire activity expected
A16: Source of Funds (onboarding) | B16: Retail cell-phone repair services and accessory sales, paid by card and cash
A17: Primary Supplier (onboarding) | B17: MobileSource Parts Distribution Inc. - domestic parts distributor, paid by ACH
A18: Annual Sales (2025 KYC refresh) | B18: $310,000
A19: RM Contact Note (2026-08-20) | B19: During a routine KYC refresh call, the owner attributed higher cash deposits to increased accessory sales and said 'some customers prefer to pay cash'. He described Golden Kestrel General Trading FZE as an 'inventory supplier' and Stonebridge Crest Holdings LLC as 'my holding company'. No sales records, invoices or agreements were provided as of case open.
A21: ACCOUNTS
A22: Accounts | B22: Type | C22: Status | D22: Open Date | E22: Close Date
A23: DDA – 5523018846120 | B23: Business | C23: Open | D23: 43557
A24: DDA – 5523018851447 | B24: Personal | C24: Open | D24: 42957
A26: Related Cases | B26: None

Sheet Accounts
A1: Customer Name | C1: Northgate Mobile Repair LLC
A3: Account | B3: Account Type | C3: Account Number | D3: Account Owners | E3: # of Alerted Events | F3: Status | G3: Open Date | H3: Closed Date
A4: DDA | B4: Business | C4: 5523018846120 | D4: Northgate Mobile Repair LLC (authorized signer: Desmond J. Bennett) | E4: 9 | F4: Open | G4: 43557
A5: DDA | B5: Personal | C5: 5523018851447 | D5: Desmond J. Bennett | E5: 1 | F5: Open | G5: 42957

Sheet Event Details
A1: Case Open Date | B1: 46281
A2: Review Period | B2: 05/01/2026 – 08/31/2026
A3: Event | B3: Date | C3: Account | D3: Amount | E3: C/D | F3: Type
A4: Structuring - Cash | B4: 46181 | C4: 5523018846120 | D4: 9800 | E4: C | F4: Cash
A5: Multi-Location Cash | B5: 46181 | C5: 5523018846120 | D5: 8600 | E5: C | F5: Cash
A6: International Wire - Cash Velocity | B6: 46188 | C6: 5523018846120 | D6: -19782.15 | E6: D | F6: Wire
A7: Cash Spike vs. Profile | B7: 46204 | C7: 5523018846120 | D7: 8850 | E7: C | F7: Cash
A8: Structuring - Cash | B8: 46209 | C8: 5523018846120 | D8: 9950 | E8: C | F8: Cash
A9: High Value Wire - Foreign | B9: 46218 | C9: 5523018846120 | D9: -27835.6 | E9: D | F9: Wire
A10: Structuring - Cash | B10: 46230 | C10: 5523018846120 | D10: 9700 | E10: C | F10: Cash
A11: Structuring - Cash (Multi-Account) | B11: 46230 | C11: 5523018851447 | D11: 9200 | E11: C | F11: Cash
A12: Structuring - Cash | B12: 46245 | C12: 5523018846120 | D12: 9300 | E12: C | F12: Cash
A13: Rapid Movement of Funds - Wire | B13: 46248 | C13: 5523018846120 | D13: -26410.3 | E13: D | F13: Wire

Sheet Transactions
A1: Name | B1: Account | C1: P/B | D1: Daily Balance | E1: Date | F1: Credit | G1: Debit | H1: Type | I1: C/D | J1: Group | K1: Description | L1: Debit Card No. | M1: Check No | N1: City | O1: State | P1: Zip | Q1: Branch Ref | R1: Teller Ref | S1: Terminal ID | T1: Local Time | U1: Post Date | V1: Sender Name | W1: Sender Bank | X1: Sender Account Number | Y1: Recipient Name | Z1: Recipient Bank | AA1: Recipient Account | AB1: Transaction Note
A2: Northgate Mobile Repair LLC | B2: 5523018846120 | C2: B | D2: =21486.37+F2-G2 -> 16636.37 | E2: 46143 | F2: 0 | G2: 4850 | H2: ACH | I2: D | J2: Group 9 | K2: ACH debit - Kessler Commons Properties LLC - RENT 05/2026 | T2: 0.22916667 | U2: 46143 | V2: Northgate Mobile Repair LLC | W2: Harborview National Bank, N.A. | X2: 5523018846120 | Y2: Kessler Commons Properties LLC | Z2: Tidewell Commerce Trust | AA2: 6620193377
A3: Northgate Mobile Repair LLC | B3: 5523018846120 | C3: B | D3: =D2+F3-G3 -> 22050.74 | E3: 46146 | F3: 5414.37 | G3: 0 | H3: Card Settlement | I3: C | J3: Group 7 | K3: Merchant card settlement - Cardline Merchant Services - batch 0504 | T3: 0.17708333 | U3: 46146 | V3: Cardline Merchant Services | W3: Tidewell Commerce Trust | X3: 8800412290 | Y3: Northgate Mobile Repair LLC | Z3: Harborview National Bank, N.A. | AA3: 5523018846120
A4: Northgate Mobile Repair LLC | B4: 5523018846120 | C4: B | D4: =D3+F4-G4 -> 33290.74 | E4: 46147 | F4: 11240 | G4: 0 | H4: Cash | I4: C | J4: Group 5 | K4: Teller cash deposit | N4: Columbus | O4: OH | P4: 43229 | Q4: HNB-B12 Northland | R4: T-OH-127 | T4: 0.45 | U4: 46147 | V4: Desmond J. Bennett | Y4: Northgate Mobile Repair LLC | Z4: Harborview National Bank, N.A. | AA4: 5523018846120 | AB4: Cash in over $10,000 - CTR filed; conductor Desmond J. Bennett (owner), ID verified
A5: Northgate Mobile Repair LLC | B5: 5523018846120 | C5: B | D5: =D4+F5-G5 -> 34555.42 | E5: 46149 | F5: 1264.68 | G5: 0 | H5: Cash | I5: C | J5: Group 8 | K5: Night depository cash deposit - store receipts | N5: Columbus | O5: OH | P5: 43229 | Q5: HNB-B12 Northland | R5: T-OH-NDP | T5: 0.29513889 | U5: 46149 | V5: Northgate Mobile Repair LLC | Y5: Northgate Mobile Repair LLC | Z5: Harborview National Bank, N.A. | AA5: 5523018846120 | AB5: Night drop bag prepared by Luis A. Ortega (store manager)
A6: Northgate Mobile Repair LLC | B6: 5523018846120 | C6: B | D6: =D5+F6-G6 -> 29383.38 | E6: 46150 | F6: 0 | G6: 5172.04 | H6: ACH | I6: D | J6: Group 9 | K6: ACH debit - PayBridge Payroll Services - PAYROLL | T6: 0.22916667 | U6: 46150 | V6: Northgate Mobile Repair LLC | W6: Harborview National Bank, N.A. | X6: 5523018846120 | Y6: PayBridge Payroll Services | Z6: Tidewell Commerce Trust | AA6: 4471100825
A7: Northgate Mobile Repair LLC | B7: 5523018846120 | C7: B | D7: =D6+F7-G7 -> 34808.77 | E7: 46153 | F7: 5425.39 | G7: 0 | H7: Card Settlement | I7: C | J7: Group 7 | K7: Merchant card settlement - Cardline Merchant Services - batch 0511 | T7: 0.17708333 | U7: 46153 | V7: Cardline Merchant Services | W7: Tidewell Commerce Trust | X7: 8800412290 | Y7: Northgate Mobile Repair LLC | Z7: Harborview National Bank, N.A. | AA7: 5523018846120
A8: Northgate Mobile Repair LLC | B8: 5523018846120 | C8: B | D8: =D7+F8-G8 -> 31921.93 | E8: 46155 | F8: 0 | G8: 2886.84 | H8: ACH | I8: D | J8: Group 9 | K8: ACH debit - MobileSource Parts Distribution Inc. - INV MS-40228 | T8: 0.22916667 | U8: 46155 | V8: Northgate Mobile Repair LLC | W8: Harborview National Bank, N.A. | X8: 5523018846120 | Y8: MobileSource Parts Distribution Inc. | Z8: Bramblecrest Bank & Trust | AA8: 2209187764
A9: Northgate Mobile Repair LLC | B9: 5523018846120 | C9: B | D9: =D8+F9-G9 -> 30706.93 | E9: 46156 | F9: 0 | G9: 1215 | H9: Check | I9: D | J9: Other | K9: Check #1186 paid - Kessler Commons Properties LLC | M9: 1186 | T9: 0.25694444 | U9: 46156 | V9: Northgate Mobile Repair LLC | W9: Harborview National Bank, N.A. | X9: 5523018846120 | Y9: Kessler Commons Properties LLC | Z9: Tidewell Commerce Trust | AA9: 6620193377 | AB9: Memo: 2025 CAM reconciliation
A10: Northgate Mobile Repair LLC | B10: 5523018846120 | C10: B | D10: =D9+F10-G10 -> 27456.93 | E10: 46157 | F10: 0 | G10: 3250 | H10: Internal Transfer | I10: D | J10: Other | K10: Online transfer to personal checking ...1447 - owner draw | Q10: Online Banking | T10: 0.34166667 | U10: 46157 | V10: Northgate Mobile Repair LLC | W10: Harborview National Bank, N.A. | X10: 5523018846120 | Y10: Desmond J. Bennett | Z10: Harborview National Bank, N.A. | AA10: 5523018851447
A11: Northgate Mobile Repair LLC | B11: 5523018846120 | C11: B | D11: =D10+F11-G11 -> 33025.06 | E11: 46160 | F11: 5568.13 | G11: 0 | H11: Card Settlement | I11: C | J11: Group 7 | K11: Merchant card settlement - Cardline Merchant Services - batch 0518 | T11: 0.17708333 | U11: 46160 | V11: Cardline Merchant Services | W11: Tidewell Commerce Trust | X11: 8800412290 | Y11: Northgate Mobile Repair LLC | Z11: Harborview National Bank, N.A. | AA11: 5523018846120
A12: Northgate Mobile Repair LLC | B12: 5523018846120 | C12: B | D12: =D11+F12-G12 -> 32446.2 | E12: 46160 | F12: 0 | G12: 578.86 | H12: ACH | I12: D | J12: Group 9 | K12: ACH debit - Olentangy Electric & Gas - COMMERCIAL UTILITY | T12: 0.22916667 | U12: 46160 | V12: Northgate Mobile Repair LLC | W12: Harborview National Bank, N.A. | X12: 5523018846120 | Y12: Olentangy Electric & Gas | Z12: Tidewell Commerce Trust | AA12: 3390022184
A13: Northgate Mobile Repair LLC | B13: 5523018846120 | C13: B | D13: =D12+F13-G13 -> 41846.2 | E13: 46161 | F13: 9400 | G13: 0 | H13: Cash | I13: C | J13: Group 1 | K13: Teller cash deposit | N13: Columbus | O13: OH | P13: 43229 | Q13: HNB-B12 Northland | R13: T-OH-127 | T13: 0.43194444 | U13: 46161 | V13: Desmond J. Bennett | Y13: Northgate Mobile Repair LLC | Z13: Harborview National Bank, N.A. | AA13: 5523018846120 | AB13: Depositor: Desmond J. Bennett (owner); in-person teller deposit
A14: Northgate Mobil Repair LLC | B14: 5523018846120 | C14: B | D14: =D13+F14-G14 -> 51096.2 | E14: 46162 | F14: 9250 | G14: 0 | H14: Cash | I14: C | J14: Group 1 | K14: Teller cash deposit | N14: Westerville | O14: OH | P14: 43081 | Q14: HNB-B27 Westerville | R14: T-OH-274 | T14: 0.49097222 | U14: 46162 | V14: Luis A. Ortega | Y14: Northgate Mobile Repair LLC | Z14: Harborview National Bank, N.A. | AA14: 5523018846120 | AB14: Depositor: Luis A. Ortega (store manager, authorized depositor); in-person teller deposit
A15: Northgate Mobile Repair LLC | B15: 5523018846120 | C15: B | D15: =D14+F15-G15 -> 45837.73 | E15: 46164 | F15: 0 | G15: 5258.47 | H15: ACH | I15: D | J15: Group 9 | K15: ACH debit - PayBridge Payroll Services - PAYROLL | T15: 0.22916667 | U15: 46164 | V15: Northgate Mobile Repair LLC | W15: Harborview National Bank, N.A. | X15: 5523018846120 | Y15: PayBridge Payroll Services | Z15: Tidewell Commerce Trust | AA15: 4471100825
A16: Northgate Mobile Repair LLC | B16: 5523018846120 | C16: B | D16: =D15+F16-G16 -> 51366.31 | E16: 46168 | F16: 5528.58 | G16: 0 | H16: Card Settlement | I16: C | J16: Group 7 | K16: Merchant card settlement - Cardline Merchant Services - batch 0526 | T16: 0.17708333 | U16: 46168 | V16: Cardline Merchant Services | W16: Tidewell Commerce Trust | X16: 8800412290 | Y16: Northgate Mobile Repair LLC | Z16: Harborview National Bank, N.A. | AA16: 5523018846120
A17: Northgate Mobile Repair LLC | B17: 5523018846120 | C17: B | D17: =D16+F17-G17 -> 26849.91 | E17: 46168 | F17: 0 | G17: 24516.4 | H17: Wire | I17: D | J17: Group 2 | K17: Outgoing international wire (USD) - Golden Kestrel General Trading FZE | Q17: Online Banking | T17: 0.42013889 | U17: 46168 | V17: Northgate Mobile Repair LLC | W17: Harborview National Bank, N.A. | X17: 5523018846120 | Y17: Golden Kestrel General Trading FZE | Z17: Dunecrest Commercial Bank PJSC, Dubai, UAE | AA17: AE07 0450 **** **** 1862 | AB17: Currency USD; OBI: INVENTORY; Bene address: Warehouse 14, Free Zone South, Dubai, UAE; Bene country AE - HNB country-risk rating: Medium (not FATF-listed); OFAC screen: no match; New beneficiary added via online banking 05/26/2026
A18: Northgate Mobile Repair LLC | B18: 5523018846120 | C18: B | D18: =D17+F18-G18 -> 23560.79 | E18: 46169 | F18: 0 | G18: 3289.12 | H18: ACH | I18: D | J18: Group 9 | K18: ACH debit - MobileSource Parts Distribution Inc. - INV MS-40256 | T18: 0.22916667 | U18: 46169 | V18: Northgate Mobile Repair LLC | W18: Harborview National Bank, N.A. | X18: 5523018846120 | Y18: MobileSource Parts Distribution Inc. | Z18: Bramblecrest Bank & Trust | AA18: 2209187764
A19: Northgate Mobile Repair LLC | B19: 5523018846120 | C19: B | D19: =D18+F19-G19 -> 24765.23 | E19: 46170 | F19: 1204.44 | G19: 0 | H19: Cash | I19: C | J19: Group 8 | K19: Night depository cash deposit - store receipts | N19: Columbus | O19: OH | P19: 43229 | Q19: HNB-B12 Northland | R19: T-OH-NDP | T19: 0.29513889 | U19: 46170 | V19: Northgate Mobile Repair LLC | Y19: Northgate Mobile Repair LLC | Z19: Harborview National Bank, N.A. | AA19: 5523018846120 | AB19: Night drop bag prepared by Luis A. Ortega (store manager)
A20: Northgate Mobile Repair LLC | B20: 5523018846120 | C20: B | D20: =D19+F20-G20 -> 24639.69 | E20: 46171 | F20: 0 | G20: 125.54 | H20: Fee | I20: D | J20: Other | K20: Account analysis fee - 05/2026 (maintenance, cash handling, wire services) | T20: 0.97916667 | U20: 46171 | AB20: Maintenance $32.00; cash handling $48.54 ($1.50 per $1,000 of $32,359.12 cash deposited); 1 international wire(s) at $45.00; 0 domestic wire(s) at $30.00
A21: Northgate Mobile Repair LLC | B21: 5523018846120 | C21: B | D21: =D20+F21-G21 -> 29749.39 | E21: 46174 | F21: 5109.7 | G21: 0 | H21: Card Settlement | I21: C | J21: Group 7 | K21: Merchant card settlement - Cardline Merchant Services - batch 0601 | T21: 0.17708333 | U21: 46174 | V21: Cardline Merchant Services | W21: Tidewell Commerce Trust | X21: 8800412290 | Y21: Northgate Mobile Repair LLC | Z21: Harborview National Bank, N.A. | AA21: 5523018846120
A22: Northgate Mobile Repair LLC | B22: 5523018846120 | C22: B | D22: =D21+F22-G22 -> 24899.39 | E22: 46174 | F22: 0 | G22: 4850 | H22: ACH | I22: D | J22: Group 9 | K22: ACH debit - Kessler Commons Properties LLC - RENT 06/2026 | T22: 0.22916667 | U22: 46174 | V22: Northgate Mobile Repair LLC | W22: Harborview National Bank, N.A. | X22: 5523018846120 | Y22: Kessler Commons Properties LLC | Z22: Tidewell Commerce Trust | AA22: 6620193377
A23: Northgate Mobile Repair LLC | B23: 5523018846120 | C23: B | D23: =D22+F23-G23 -> 19807.73 | E23: 46178 | F23: 0 | G23: 5091.66 | H23: ACH | I23: D | J23: Group 9 | K23: ACH debit - PayBridge Payroll Services - PAYROLL | T23: 0.22916667 | U23: 46178 | V23: Northgate Mobile Repair LLC | W23: Harborview National Bank, N.A. | X23: 5523018846120 | Y23: PayBridge Payroll Services | Z23: Tidewell Commerce Trust | AA23: 4471100825
A24: Northgate Mobile Repair LLC | B24: 5523018846120 | C24: B | D24: =D23+F24-G24 -> 25135.18 | E24: 46181 | F24: 5327.45 | G24: 0 | H24: Card Settlement | I24: C | J24: Group 7 | K24: Merchant card settlement - Cardline Merchant Services - batch 0608 | T24: 0.17708333 | U24: 46181 | V24: Cardline Merchant Services | W24: Tidewell Commerce Trust | X24: 8800412290 | Y24: Northgate Mobile Repair LLC | Z24: Harborview National Bank, N.A. | AA24: 5523018846120
A25: Northgate Mobile Repair LLC | B25: 5523018846120 | C25: B | D25: =D24+F25-G25 -> 34935.18 | E25: 46181 | F25: 9800 | G25: 0 | H25: Cash | I25: C | J25: Group 1 | K25: Teller cash deposit | N25: Columbus | O25: OH | P25: 43229 | Q25: HNB-B12 Northland | R25: T-OH-127 | T25: 0.40347222 | U25: 46181 | V25: Desmond J. Bennett | Y25: Northgate Mobile Repair LLC | Z25: Harborview National Bank, N.A. | AA25: 5523018846120 | AB25: Depositor: Desmond J. Bennett (owner); in-person teller deposit; aggregated with same-day deposit at Westerville - CTR filed for business day 06/08/2026, total $18,400.00
A26: Northgate Mobil Repair LLC | B26: 5523018846120 | C26: B | D26: =D25+F26-G26 -> 43535.18 | E26: 46181 | F26: 8600 | G26: 0 | H26: Cash | I26: C | J26: Group 1 | K26: Teller cash deposit | N26: Westerville | O26: OH | P26: 43081 | Q26: HNB-B27 Westerville | R26: T-OH-274 | T26: 0.47638889 | U26: 46181 | V26: Luis A. Ortega | Y26: Northgate Mobile Repair LLC | Z26: Harborview National Bank, N.A. | AA26: 5523018846120 | AB26: Depositor: Luis A. Ortega (store manager, authorized depositor); in-person teller deposit; aggregated with same-day deposit at Northland - CTR filed for business day 06/08/2026, total $18,400.00
A27: Northgate Mobile Repair LLC | B27: 5523018846120 | C27: B | D27: =D26+F27-G27 -> 40562.12 | E27: 46183 | F27: 0 | G27: 2973.06 | H27: ACH | I27: D | J27: Group 9 | K27: ACH debit - MobileSource Parts Distribution Inc. - INV MS-40279 | T27: 0.22916667 | U27: 46183 | V27: Northgate Mobile Repair LLC | W27: Harborview National Bank, N.A. | X27: 5523018846120 | Y27: MobileSource Parts Distribution Inc. | Z27: Bramblecrest Bank & Trust | AA27: 2209187764
A28: Northgate Mobile Repair LLC | B28: 5523018846120 | C28: B | D28: =D27+F28-G28 -> 49712.12 | E28: 46183 | F28: 9150 | G28: 0 | H28: Cash | I28: C | J28: Group 1 | K28: Teller cash deposit | N28: Worthington | O28: OH | P28: 43085 | Q28: HNB-B33 Worthington | R28: T-OH-335 | T28: 0.63333333 | U28: 46183 | V28: Desmond J. Bennett | Y28: Northgate Mobile Repair LLC | Z28: Harborview National Bank, N.A. | AA28: 5523018846120 | AB28: Depositor: Desmond J. Bennett (owner); in-person teller deposit
A29: Northgate Mobile Repair LLC | B29: 5523018846120 | C29: B | D29: =D28+F29-G29 -> 50783.51 | E29: 46184 | F29: 1071.39 | G29: 0 | H29: Cash | I29: C | J29: Group 8 | K29: Night depository cash deposit - store receipts | N29: Columbus | O29: OH | P29: 43229 | Q29: HNB-B12 Northland | R29: T-OH-NDP | T29: 0.29513889 | U29: 46184 | V29: Northgate Mobile Repair LLC | Y29: Northgate Mobile Repair LLC | Z29: Harborview National Bank, N.A. | AA29: 5523018846120 | AB29: Night drop bag prepared by Luis A. Ortega (store manager)
A30: Northgate Mobile Repair LLC | B30: 5523018846120 | C30: B | D30: =D29+F30-G30 -> 35783.51 | E30: 46185 | F30: 0 | G30: 15000 | H30: Wire | I30: D | J30: Group 3 | K30: Outgoing domestic wire (USD) - Stonebridge Crest Holdings LLC | Q30: Online Banking | T30: 0.46458333 | U30: 46185 | V30: Northgate Mobile Repair LLC | W30: Harborview National Bank, N.A. | X30: 5523018846120 | Y30: Stonebridge Crest Holdings LLC | Z30: Lakemont Federal Bank | AA30: 7310045528 | AB30: OBI: CONSULTING; Bene address: 7720 Saddle Creek Ct, Dublin, OH 43017
A31: Northgate Mobile Repair LLC | B31: 5523018846120 | C31: B | D31: =D30+F31-G31 -> 41309.98 | E31: 46188 | F31: 5526.47 | G31: 0 | H31: Card Settlement | I31: C | J31: Group 7 | K31: Merchant card settlement - Cardline Merchant Services - batch 0615 | T31: 0.17708333 | U31: 46188 | V31: Cardline Merchant Services | W31: Tidewell Commerce Trust | X31: 8800412290 | Y31: Northgate Mobile Repair LLC | Z31: Harborview National Bank, N.A. | AA31: 5523018846120
A32: Northgate Mobile Repair LLC | B32: 5523018846120 | C32: B | D32: =D31+F32-G32 -> 38059.98 | E32: 46188 | F32: 0 | G32: 3250 | H32: Internal Transfer | I32: D | J32: Other | K32: Online transfer to personal checking ...1447 - owner draw | Q32: Online Banking | T32: 0.34166667 | U32: 46188 | V32: Northgate Mobile Repair LLC | W32: Harborview National Bank, N.A. | X32: 5523018846120 | Y32: Desmond J. Bennett | Z32: Harborview National Bank, N.A. | AA32: 5523018851447
A33: Northgate Mobile Repair LLC | B33: 5523018846120 | C33: B | D33: =D32+F33-G33 -> 18277.83 | E33: 46188 | F33: 0 | G33: 19782.15 | H33: Wire | I33: D | J33: Group 2 | K33: Outgoing international wire (USD) - Golden Kestrel General Trading FZE | Q33: Online Banking | T33: 0.43819444 | U33: 46188 | V33: Northgate Mobile Repair LLC | W33: Harborview National Bank, N.A. | X33: 5523018846120 | Y33: Golden Kestrel General Trading FZE | Z33: Dunecrest Commercial Bank PJSC, Dubai, UAE | AA33: AE07 0450 **** **** 1862 | AB33: Currency USD; OBI: CONSULTING SERVICES; Bene address: Warehouse 14, Free Zone South, Dubai, UAE; Bene country AE - HNB country-risk rating: Medium (not FATF-listed); OFAC screen: no match
A34: Northgate Mobile Repair LLC | B34: 5523018846120 | C34: B | D34: =D33+F34-G34 -> 17649.69 | E34: 46190 | F34: 0 | G34: 628.14 | H34: ACH | I34: D | J34: Group 9 | K34: ACH debit - Olentangy Electric & Gas - COMMERCIAL UTILITY | T34: 0.22916667 | U34: 46190 | V34: Northgate Mobile Repair LLC | W34: Harborview National Bank, N.A. | X34: 5523018846120 | Y34: Olentangy Electric & Gas | Z34: Tidewell Commerce Trust | AA34: 3390022184
A35: Northgate Mobile Repair LLC | B35: 5523018846120 | C35: B | D35: =D34+F35-G35 -> 12737.51 | E35: 46191 | F35: 0 | G35: 4912.18 | H35: ACH | I35: D | J35: Group 9 | K35: ACH debit - PayBridge Payroll Services - PAYROLL | T35: 0.22916667 | U35: 46191 | V35: Northgate Mobile Repair LLC | W35: Harborview National Bank, N.A. | X35: 5523018846120 | Y35: PayBridge Payroll Services | Z35: Tidewell Commerce Trust | AA35: 4471100825
A36: Northgate Mobile Repair LLC | B36: 5523018846120 | C36: B | D36: =D35+F36-G36 -> 18111.98 | E36: 46195 | F36: 5374.47 | G36: 0 | H36: Card Settlement | I36: C | J36: Group 7 | K36: Merchant card settlement - Cardline Merchant Services - batch 0622 | T36: 0.17708333 | U36: 46195 | V36: Cardline Merchant Services | W36: Tidewell Commerce Trust | X36: 8800412290 | Y36: Northgate Mobile Repair LLC | Z36: Harborview National Bank, N.A. | AA36: 5523018846120
A37: Northgate Mobile Repair LLC | B37: 5523018846120 | C37: B | D37: =D36+F37-G37 -> 36761.98 | E37: 46195 | F37: 18650 | G37: 0 | H37: ACH | I37: C | J37: Group 6 | K37: ACH credit - Buckeye Shield Mutual Insurance Co. - CLAIM CP-2026-044718 | T37: 0.22916667 | U37: 46195 | V37: Buckeye Shield Mutual Insurance Co. | W37: Tidewell Commerce Trust | X37: 9014452260 | Y37: Northgate Mobile Repair LLC | Z37: Harborview National Bank, N.A. | AA37: 5523018846120 | AB37: Commercial property claim CP-2026-044718 - water damage at store, loss date 06/03/2026
A38: Northgate Mobile Repair LLC | B38: 5523018846120 | C38: B | D38: =D37+F38-G38 -> 33674.46 | E38: 46197 | F38: 0 | G38: 3087.52 | H38: ACH | I38: D | J38: Group 9 | K38: ACH debit - MobileSource Parts Distribution Inc. - INV MS-40297 | T38: 0.22916667 | U38: 46197 | V38: Northgate Mobile Repair LLC | W38: Harborview National Bank, N.A. | X38: 5523018846120 | Y38: MobileSource Parts Distribution Inc. | Z38: Bramblecrest Bank & Trust | AA38: 2209187764
A39: Northgate Mobile Repair LLC | B39: 5523018846120 | C39: B | D39: =D38+F39-G39 -> 34917.05 | E39: 46198 | F39: 1242.59 | G39: 0 | H39: Cash | I39: C | J39: Group 8 | K39: Night depository cash deposit - store receipts | N39: Columbus | O39: OH | P39: 43229 | Q39: HNB-B12 Northland | R39: T-OH-NDP | T39: 0.29513889 | U39: 46198 | V39: Northgate Mobile Repair LLC | Y39: Northgate Mobile Repair LLC | Z39: Harborview National Bank, N.A. | AA39: 5523018846120 | AB39: Night drop bag prepared by Luis A. Ortega (store manager)
A40: Northgate Mobile Repair LLC | B40: 5523018846120 | C40: B | D40: =D39+F40-G40 -> 23117.05 | E40: 46199 | F40: 0 | G40: 11800 | H40: Check | I40: D | J40: Group 6 | K40: Check #1187 paid - Ridgeway Build & Restore LLC | M40: 1187 | T40: 0.25694444 | U40: 46199 | V40: Northgate Mobile Repair LLC | W40: Harborview National Bank, N.A. | X40: 5523018846120 | Y40: Ridgeway Build & Restore LLC | Z40: Bramblecrest Bank & Trust | AA40: 5580031946 | AB40: Memo: water damage repairs - claim CP-2026-044718
...

Sheet Support_Docs
A1: Insert any supporting documents (statements, ID, correspondence) on this tab. Not required for this practice case.

Sheet Open_Source_Research
A1: Insert screenshots of your open-source research on this tab. Each screenshot must show the source link (URL). Not required for this practice case.

Sheet Disposition & Narrative
A1: Harborview National Bank, N.A. (HNB) is filing this SAR to report suspected structuring of cash deposits, followed by rapid wire transfers, involving Northgate Mobile Repair LLC (Northgate), a Columbus, Ohio cell-phone repair business, and its owner and managing member, Desmond J. Bennett. Between May 19, 2026 and August 18, 2026, 16 cash deposits totaling $148,150.00, each between $8,400.00 and $9,950.00, were made to Northgate's business account and Mr. Bennett's personal account, and seven wires totaling $140,044.45 were sent to Golden Kestrel General Trading FZE in Dubai, United Arab Emirates, and to Stonebridge Crest Holdings LLC, an entity linked to Mr. Bennett. The total suspicious activity is $288,194.45. The primary concern is that cash was deposited in amounts kept below the $10,000 currency transaction reporting threshold and then wired out of the bank within days. Northgate (TIN XX-XXX7316) has banked with HNB since April 2019 and holds business checking account 5523018846120; Mr. Bennett holds personal checking account 5523018851447. Northgate's KYC profile anticipates $20,000-$28,000 per month in card settlements, $2,000-$4,000 per month in night-depository cash and no international wires. On May 5, 2026, Mr. Bennett deposited $11,240.00 in cash at the Northland branch and a Currency Transaction Report (CTR) was filed; no later single cash deposit exceeded $10,000. From May 19, 2026 to August 12, 2026, Mr. Bennett made eleven teller cash deposits ($103,750.00) and store manager Luis A. Ortega made five ($44,400.00), at HNB's Northland (Columbus), Westerville, Worthington and Dublin branches, often on consecutive days. On June 8, $9,800.00 was deposited at Northland and $8,600.00 at Westerville; on July 27, Mr. Bennett deposited $9,700.00 to the business account at Northland and $9,200.00 to his personal account at Dublin. Treating each pair as one business day's cash, HNB filed CTRs for $18,400.00 and $18,900.00; no other business day exceeded $10,000. Within two to six days of each cluster, a wire was initiated: four wires totaling $98,544.45 went to Golden Kestrel on May 26, June 15, July 15 and August 14, with memos citing "inventory" or "consulting," and three totaling $41,500.00 went to Stonebridge Crest at Lakemont Federal Bank on June 12, July 30 (from the personal account) and August 18, citing "consulting," "loan repayment" and "management fee." The July 9 wire ($27,835.60), sent three days after the July 6 deposit to a misspelled beneficiary, was returned July 14 and re-sent July 15; it is counted once. Weekly card settlements totaled $96,728.59, consistent with the KYC profile, and were largely used for rent, payroll, parts-supplier and utility payments totaling $90,883.54. Established parts-supplier payments continued normally, and night-depository cash ($9,812.25) matched expected sales. An $18,650.00 insurance claim payment on June 22 was spent on repairs and equipment and is excluded. On August 20, 2026, Mr. Bennett told his relationship manager that cash rose with accessory sales, that Golden Kestrel is an inventory supplier and that Stonebridge Crest, whose beneficiary address is his residence, is his holding company; he provided no sales records, invoices or agreements. Although payments to an owner's holding company can be owner compensation, the stated purpose changed with each payment, one came from his personal account, and each followed sub-threshold cash deposits. The activity is suspicious because cash deposits totaled $169,202.25 in four months, more than ten times the $16,000 implied by the KYC profile, while card settlements stayed steady; after one reportable deposit, every later teller deposit was kept below $10,000 and spread across four branches, two depositors and two accounts, exceeding the threshold only when same-day deposits were aggregated by the bank; and the funds were quickly wired to a foreign general-trading company with no documented link to phone repair and to an owner-linked entity. The source of the cash and the purpose of the wires remain unexplained. Supporting documentation, including account statements, teller deposit records, CTRs dated 05/05, 06/08 and 07/27/2026, wire records and the KYC file, is retained by HNB and available upon request.
A3: Model narrative (Instructor Key). Trainees enter their narrative in cell A1 only.

Sheet SAR Structured Form
A1: SAR STRUCTURED FORM
A2: Complete this form ONLY if your disposition is to file a SAR. If your disposition is No SAR, leave every field blank.
A3: How to complete: choose X from the drop-down in the shaded box to the LEFT of each option that applies; type text answers in the shaded boxes in column D.
A4: Instructor key legend: X = required; (ok) = acceptable, neither required nor penalised; anything else ticked = incorrect
A6: PART I – FILING INSTITUTION, SUBJECT AND ACCOUNT INFORMATION
B7: Events | D7: Structuring - Cash; Multi-Location Cash; International Wire - Cash Velocity; Cash Spike vs. Profile; High Value Wire - Foreign; Structuring - Cash (Multi-Account); Rapid Movement of Funds - Wire (10 alerted events, 06/08/2026-08/14/2026; 9 on account 5523018846120, 1 on account 5523018851447)
B8: Report on Following RFI (filing institution) | D8: Harborview National Bank, N.A.
B9: Suspect(s) (one per line) | D9: Northgate Mobile Repair LLC (DBA Northgate Phone Fix), TIN XX-XXX7316, 4127 Kessler Commons Blvd, Suite C, Columbus, OH 43229 Desmond J. Bennett, managing member / 100% owner, 7720 Saddle Creek Ct, Dublin, OH 43017 | E9: (ok) Luis A. Ortega, store manager of Northgate Mobile Repair LLC - conductor of 5 structured cash deposits ($44,400.00)
B10: Report on the following Account(s) (one per line) | D10: 5523018846120 - business checking - Northgate Mobile Repair LLC (open) 5523018851447 - personal checking - Desmond J. Bennett (open)
A12: BRANCH INFORMATION
A13: # | B13: Branch Name | D13: City | E13: State
A14: 1 | B14: Harborview National Bank - Northland Branch | D14: Columbus | E14: OH
A15: 2 | B15: Harborview National Bank - Westerville Branch | D15: Westerville | E15: OH
A16: 3 | B16: Harborview National Bank - Worthington Branch | D16: Worthington | E16: OH
A17: 4 | B17: Harborview National Bank - Dublin Branch | D17: Dublin | E17: OH
A18: 5
A19: 6
A20: 7
A21: 8
A23: PART II – SUSPICIOUS ACTIVITY INFORMATION
B24: 29 Amount Involved in this report $ | D24: 288195 | E24: (ok) $299,435
B25: 30 Date or date range – From | D25: 46161 | E25: (ok) 05/05/2026
B26: 30 Date or date range – To | D26: 46252
B27: 31 Cumulative amount (continuing activity only)
A29: 32 Structuring
B30: a. Alters or cancels transaction to avoid BSA recordkeeping requirement | C30: X | D30: e. Multiple transactions below CTR threshold
B31: b. Alters or cancels transaction to avoid CTR requirement | D31: f. Suspicious inquiry by customer regarding BSA reporting or recordkeeping requirements
B32: c. Customer cancels transaction to avoid BSA reporting and recordkeeping requirements | D32: z. Other (describe in the narrative)
B33: d. Multiple transactions below BSA recordkeeping threshold
A35: 36 Money Laundering
B36: a. Exchange small bills for large bills or vice versa | D36: h. Suspicious receipt of government payments/benefits
B37: b. Funnel account | D37: i. Suspicious use of multiple accounts (ok)
B38: c. Suspicion concerning the physical condition of funds | D38: j. Suspicious use of noncash monetary instruments
A39: X | B39: d. Suspicion concerning the source of funds | D39: k. Suspicious use of third-party transactors (straw-man)
B40: e. Suspicious designation of beneficiaries, assignees or joint owners | D40: l. Trade-based money laundering / Black Market Peso Exchange
A41: X | B41: f. Suspicious EFT/wire transfers | D41: m. Transaction out of pattern for customer(s) (ok)
B42: g. Suspicious exchange of currencies | D42: z. Other (describe in the narrative)
A44: 38 Other Suspicious Activities
B45: a. Account takeover | D45: k. Misuse of position or self-dealing
B46: b. Bribery or gratuity | D46: l. Suspected public/private corruption (domestic)
...

Sheet Case Study Questions
A1: CASE STUDY QUESTIONNAIRE
A2: Select one answer per question by entering X in column A (use the drop-down).
A4: SELECT | B4: OPTION | C4: ANSWER
A5: 1. Counting each completed transaction once, add the teller cash deposits that were each under $10,000 to the completed wires to Golden Kestrel General Trading FZE and Stonebridge Crest Holdings LLC. What is the result?
B6: A | C6: $244,344.45
B7: B | C7: $316,030.05
A8: X | B8: C | C8: $288,194.45
B9: D | C9: $298,006.70
A11: 2. An $18,650.00 ACH credit posted to the business account on 06/22/2026, about three weeks before the largest wire to Golden Kestrel. How should it be treated in the analysis?
B12: A | C12: Include it: any single credit over $10,000 in the review period belongs in the unexplained total.
A13: X | B13: B | C13: Exclude it: a documented insurance claim (CP-2026-044718) spent on a repair contractor and equipment.
B14: C | C14: Include it: it was the source of the 07/15/2026 wire of $27,835.60 to Golden Kestrel.
B15: D | C15: Include only the $910.00 that was not spent on the repair contractor or the equipment.
A17: 3. Which fact most strongly indicates that the cash deposits were structured to avoid currency transaction reporting, rather than reflecting busier trading?
B18: A | C18: Cash deposits totaled $169,202.25 over the four months, far above the KYC expectation of $2,000-$4,000 per month.
B19: B | C19: The store manager, as well as the owner, made several of the in-person teller cash deposits at the branches.
B20: C | C20: The larger deposits were made in person at a teller rather than through the business's night depository.
A21: X | B21: D | C21: After a CTR was filed on the 05/05 deposit, every later teller deposit was $8,400-$9,950, often split across branches.
A23: 4. Card settlements are a mitigating factor. What does the transaction trail show about their link to the outgoing wires?
A24: X | B24: A | C24: No link: settlements stayed in the KYC range and were largely spent on rent, payroll, parts and utilities.
B25: B | C25: They funded the wires: settlement amounts rose in the weeks before each wire, in line with accessory sales.
B26: C | C26: They funded the Stonebridge Crest wires, while the cash deposits funded the Golden Kestrel wires.
B27: D | C27: It cannot be determined, because weekly settlement batches cannot be matched to specific outgoing wires.
A29: 5. Which branches were used to conduct the cash deposits and wires that are not explained by the business's legitimate income?
B30: A | C30: Northland (Columbus), Westerville and Online Banking
B31: B | C31: Northland (Columbus), Worthington and Dublin
A32: X | B32: C | C32: Northland (Columbus), Westerville, Worthington and Dublin
B33: D | C33: Northland (Columbus), Westerville, Worthington, Dublin and Online Banking
A35: 6. Which entries belong in SAR Fields 29 and 30 for this case?
B36: A | C36: $316,031 | 05/19/2026 - 08/18/2026
B37: B | C37: $288,195 | 06/08/2026 - 08/14/2026
B38: C | C38: None - the disposition does not support filing, so the form stays blank
A39: X | B39: D | C39: $288,195 | 05/19/2026 - 08/18/2026
A41: 7. If a SAR is filed, which Part II boxes best describe the outgoing wires to Golden Kestrel General Trading FZE?
B42: A | C42: 36 l Trade-based money laundering and 46 c Funds transfer
A43: X | B43: B | C43: 36 f Suspicious EFT/wire transfers and 46 c Funds transfer
B44: C | C44: 36 b Funnel account and 46 c Funds transfer
B45: D | C45: 36 f Suspicious EFT/wire transfers, 46 c Funds transfer and 46 b Foreign currency
A47: 8. Which disposition is best supported by the evidence in this workbook?
A48: X | B48: A | C48: SAR: documented card, night-drop and insurance income does not explain $148,150.00 in sub-threshold cash or $140,044.45 wired out within days.
...

Sheet Instructor – Answer Key
A1: INSTRUCTOR ONLY – not for distribution to trainees
A2: Answer Key – Practice Case A
A4: Q# | B4: Correct option | C4: Rationale | D4: Skill tested
A5: 1 | B5: C – $288,194.45 | C5: 16 teller deposits of $8,400.00-$9,950.00 ($148,150.00) plus 7 completed wires ($140,044.45) = $288,194.45. A drops the 5 Westerville deposits ($43,850.00) whose Name reads 'Northgate Mobil Repair LLC' - reconcile by account number. B also counts the 07/09/2026 wire that was returned on 07/14/2026 and re-sent on 07/15/2026. D adds the KYC-consistent night-depository cash ($9,812.25), which is not teller cash. | D5: Reconciliation of totals
A6: 2 | B6: B – Exclude it: a documented insurance claim (CP-2026-044718) spent on a repair contractor and equipment. | C6: The credit names the insurer and claim number, follows a documented loss (water damage, 06/03/2026) and is traced within eight days to check #1187 to Ridgeway Build & Restore LLC ($11,800.00) and an ACH to TechBench Repair Equipment Co. ($5,940.00). It is legitimate and unrelated to the cash-to-wire pattern, so no part of it belongs in the suspicious total (A, D). The 07/15 wire followed the cash build-up of 06/29-07/06, not this credit (C). | D6: Exclusion of legitimate activity
A7: 3 | B7: D – After a CTR was filed on the 05/05 deposit, every later teller deposit was $8,400-$9,950, often split across branches. | C7: Volume above profile (A) shows the activity is unusual, not that the threshold was avoided; B and C describe how the cash was deposited, not why the amounts were chosen. After one CTR-reportable deposit ($11,240.00), every later teller deposit sat in a tight band just under $10,000 and was split across branches, conductors and accounts. HNB's same-day aggregation still produced CTRs for 06/08 ($18,400.00) and 07/27 ($18,900.00), but structuring is the attempt to evade reporting - the bank catching it does not remove the indicator. | D7: Structuring red-flag identification
A8: 4 | B8: A – No link: settlements stayed in the KYC range and were largely spent on rent, payroll, parts and utilities. | C8: The 18 weekly settlements ranged only from $5,109.70 to $5,568.13 with no build-up before any wire (B), and operating payments of $90,883.54 absorbed most of the $96,728.59 received. The wires instead track the cash clusters (e.g., 08/10-08/12 cash of $27,900.00, then the 08/14 wire of $26,410.30); nothing ties settlements to Stonebridge Crest (C), and the timing evidence answers D. | D8: Source-of-funds analysis / weighing mitigating facts
A9: 5 | B9: C – Northland (Columbus), Westerville, Worthington and Dublin | C9: Unexplained deposits were conducted at Northland (5), Westerville (5), Worthington (4) and Dublin (2, plus the 07/30 personal-account wire). The Westerville rows carry the name variant 'Northgate Mobil Repair LLC', so a name filter drops them (B). Online banking is a channel, not a branch (A, D), and A also omits Worthington and Dublin. These four branches go in the SAR form's Branch Information table if a SAR is filed. | D9: Branch / location information
A10: 6 | B10: D – $288,195 | 05/19/2026 - 08/18/2026 | C10: The evidence supports filing (Q8), so C is wrong. Field 29 counts the suspicious deposits and the suspicious wires: $288,194.45 rounded UP = $288,195; A also counts the returned 07/09/2026 wire ($27,835.60), which came back and was re-sent. Field 30 runs from the first suspicious transaction (05/19/2026 deposit) to the last (08/18/2026 wire), not the alert window (B). Also acceptable: $299,435 with Field 30 from 05/05/2026, if the 05/05/2026 CTR deposit is included as unexplained cash and the narrative says so. | D10: SAR form - Fields 29 and 30
A11: 7 | B11: B – 36 f Suspicious EFT/wire transfers and 46 c Funds transfer | C11: The concern is the wires themselves: first-ever international transfers, shifting memos, no documented purpose, sent within days of the cash. The wire rows show the currency as USD, so 46 b is wrong (D). No trade documents or pricing anomalies support TBML (A), and a funnel account involves deposits by multiple parties in dispersed locations (C). 38 q is acceptable on the form if the narrative explains the basis (HNB rates the UAE Medium), so it is not offered here. | D11: SAR form - checkbox selection
A12: 8 | B12: A – SAR: documented card, night-drop and insurance income does not explain $148,150.00 in sub-threshold cash or $140,044.45 wired out within days. | C12: A follows the evidence: legitimate income is documented and explains the operating activity, but not the sub-threshold cash or the wires, and the owner produced no records. B accepts undocumented statements and ignores the structuring pattern. C confuses CTRs (currency reporting) with SARs (suspicion) - aggregation by the bank does not cure structuring. D states an unproven crime as fact; the standard is knowledge, suspicion or reason to suspect. | D12: SAR decisioning
A14: SAR FORM KEY – REQUIRED vs ACCEPTABLE ENTRIES
A15: Legend: X = required; (ok) = acceptable, neither required nor penalised; anything else ticked = incorrect
A16: SAR item | C16: Required (instructor key) | D16: Also acceptable – neither required nor penalised
A17: Events | C17: Structuring - Cash; Multi-Location Cash; International Wire - Cash Velocity; Cash Spike vs. Profile; High Value Wire - Foreign; Structuring - Cash (Multi-Account); Rapid Movement of Funds - Wire (10 alerted events, 06/08/2026-08/14/2026; 9 on account 5523018846120, 1 on account 5523018851447)
A18: Report on Following RFI (filing institution) | C18: Harborview National Bank, N.A.
A19: Suspect(s) | C19: Northgate Mobile Repair LLC (DBA Northgate Phone Fix), TIN XX-XXX7316, 4127 Kessler Commons Blvd, Suite C, Columbus, OH 43229 Desmond J. Bennett, managing member / 100% owner, 7720 Saddle Creek Ct, Dublin, OH 43017 | D19: Luis A. Ortega, store manager of Northgate Mobile Repair LLC - conductor of 5 structured cash deposits ($44,400.00)
A20: Account(s) | C20: 5523018846120 - business checking - Northgate Mobile Repair LLC (open) 5523018851447 - personal checking - Desmond J. Bennett (open)
A21: Branch information | C21: Harborview National Bank - Northland Branch, Columbus OH Harborview National Bank - Westerville Branch, Westerville OH Harborview National Bank - Worthington Branch, Worthington OH Harborview National Bank - Dublin Branch, Dublin OH
A22: 29 Amount involved | C22: $288,195 | D22: $299,435
A23: 30 Date range – From | C23: 05/19/2026 | D23: 05/05/2026
A24: 30 Date range – To | C24: 08/18/2026
A25: 31 Cumulative amount | C25: (blank)
A26: 32 Structuring | C26: e. Multiple transactions below CTR threshold
A27: 36 Money Laundering | C27: d. Suspicion concerning the source of funds f. Suspicious EFT/wire transfers | D27: i. Suspicious use of multiple accounts m. Transaction out of pattern for customer(s)
A28: 38 Other Suspicious Activities | C28: o. Suspicious use of multiple transaction locations | D28: p. Transaction with no apparent economic, business or lawful purpose q. Transaction(s) involving foreign high-risk jurisdiction r. Two or more individuals working together
A29: 45 Product type(s) involved | C29: f. Deposit account
A30: 46 Instrument type(s) / payment mechanism(s) involved | C30: c. Funds transfer i. U.S. Currency

Sheet Instructor – Fact Checklist
A1: INSTRUCTOR ONLY – not for distribution to trainees
A2: Fact Checklist – material facts a strong narrative must convey
A4: ID | B4: Fact | C4: 5W1H category | D4: Rubric section | E4: Weight (Core / Supporting / Optional) | F4: Accepted variants | G4: Critical if wrong/missing (Y/N)
A5: F01 | B5: Subjects are Northgate Mobile Repair LLC, a cell-phone repair and accessories business in Columbus, Ohio, and its owner/managing member Desmond J. Bennett. | C5: WHO | D5: Executive Summary | E5: Core | F5: Northgate; Northgate Mobile Repair; 'the business and its owner'; Columbus OH | G5: Y
A6: F02 | B6: Harborview National Bank, N.A. is filing a SAR (disposition: SAR). | C6: DECISION | D6: Executive Summary | E6: Core | F6: 'HNB is filing this SAR'; 'the bank is reporting'; disposition stated first | G6: Y
A7: F03 | B7: Total suspicious activity is $288,194.45 (Field 29: $288,195): $148,150.00 structured cash plus $140,044.45 in wires. | C7: WHAT | D7: Executive Summary | E7: Core | F7: $288,195 (key: suspicious deposits + suspicious wires). Also accepted: $299,434.45 / $299,435 with activity from 05/05/2026, if the narrative states that the 05/05/2026 CTR deposit ($11,240.00) is included as unexplained cash. A rounded total is acceptable only if both components are stated; component figures must be exact. Critical only if the components are wrong or the total includes legitimate or returned items. | G7: Y
A8: F04 | B8: Suspicious activity ran from 05/19/2026 to 08/18/2026, within the 05/01/2026-08/31/2026 review period. | C8: WHEN | D8: Executive Summary | E8: Core | F8: May 19 - August 18, 2026; from 05/05/2026 if the CTR deposit is included; review period May-August 2026 also acceptable | G8: N
A9: F05 | B9: Primary concern: cash deposits kept below the $10,000 CTR threshold, then moved out by wire within days. | C9: WHY | D9: Executive Summary | E9: Core | F9: structuring / threshold avoidance + rapid outbound wires; 'cash-in, wire-out' | G9: Y
A10: F06 | B10: Northgate has banked with HNB since April 2019 (business checking 5523018846120); KYC expects $20,000-$28,000/month card settlements, $2,000-$4,000/month cash and no international wires. | C10: BACKGROUND | D10: Customer Background | E10: Core | F10: customer since 2019; expected cash of $2,000-$4,000 per month; 'no international wire activity expected' | G10: N
A11: F07 | B11: The owner's personal checking account 5523018851447 (customer since 2017) was also used for structured cash and one wire. | C11: BACKGROUND | D11: Customer Background | E11: Supporting | F11: personal account ...1447; 'second account held by the owner' | G11: N
A12: F08 | B12: An $11,240.00 cash deposit on 05/05/2026 (CTR filed) was followed only by single deposits below $10,000. | C12: WHAT | D12: Suspicious Activity & Transaction Pattern | E12: Core | F12: May 5 deposit over $10,000; 'after a CTR was filed, deposits dropped below the threshold' | G12: N
A13: F09 | B13: 16 teller cash deposits of $8,400.00-$9,950.00 totaling $148,150.00 (13 business = $120,600.00; 3 personal = $27,550.00). | C13: WHAT | D13: Suspicious Activity & Transaction Pattern | E13: Core | F13: 16 deposits; $148,150; 'between $8,400 and $9,950'; business/personal split optional | G13: Y
A14: F10 | B14: Deposits were made at four branches: Northland (Columbus), Westerville, Worthington and Dublin, Ohio. | C14: WHERE | D14: Suspicious Activity & Transaction Pattern | E14: Supporting | F14: four branches named; 'multiple branches in the Columbus area' = partial | G14: N
A15: F11 | B15: Two depositors: Desmond J. Bennett (11 deposits, $103,750.00) and store manager Luis A. Ortega (5 deposits, $44,400.00). | C15: WHO | D15: Suspicious Activity & Transaction Pattern | E15: Supporting | F15: owner and an employee/store manager; counts optional | G15: N
... A32: F28 | B32: The UAE is described neutrally (HNB country-risk rating Medium; not FATF-listed), not as a high-risk jurisdiction without basis. | C32: WHERE | D32: Specificity, Accuracy & Supporting Information | E32: Optional | F32: neutral reference to Dubai/UAE; flag as incorrect (not critical) if called 'high-risk' without stating a basis | G32: N

Sheet Instructor – Data Traps
A1: INSTRUCTOR ONLY – not for distribution to trainees
A2: Data Traps – planted data-quality issues
A4: # | B4: Data trap | C4: Where it appears | D4: What a careful analyst should do
A5: 1 | B5: Customer-name spelling variant: the five Westerville teller deposits to the business account show 'Northgate Mobil Repair LLC' in the Name column. | C5: Transactions tab, account 5523018846120, Group 1 rows dated 05/20, 06/08, 07/01, 07/28 and 08/12/2026 (Branch Ref HNB-B27 Westerville); 5 rows, $43,850.00. | D5: Filter and reconcile by account number, not name. Include these deposits in the structured total ($148,150.00) and list the Westerville branch. Analysts who filter on the exact name understate structured cash by $43,850.00 and list only three branches.
A6: 2 | B6: CTR-reportable cash deposit early in the period ($11,240.00 on 05/05/2026, note 'CTR filed') followed by a switch to single deposits of $8,400.00-$9,950.00; the two same-day pairs (06/08 $18,400.00, 07/27 $18,900.00) carry notes showing HNB aggregated them and filed CTRs. | C6: Transactions tab: account 5523018846120, 05/05/2026, Northland (Group 5); Transaction Notes on the 06/08 and 07/27 Group 1 rows. | D6: Recognise the 05/05/2026 deposit as evidence of threshold awareness and cite it as context. Do not treat it as a below-threshold deposit; the key excludes it from Field 29 and starts Field 30 at 05/19/2026 (including it - $299,435, from 05/05/2026 - is an accepted alternative if the narrative says so). Note that the bank's aggregation caught the 06/08 and 07/27 splits: do not claim CTRs were missed, and do not treat the aggregated CTRs as resolving the concern - deposits were still kept individually below $10,000 and split across branches, conductors and accounts.
A7: 3 | B7: Large legitimate credit: $18,650.00 ACH insurance claim payment on 06/22/2026, three weeks before the largest foreign wire. | C7: Transactions tab, account 5523018846120, 06/22/2026 (Group 6), traced to check #1187 $11,800.00 on 06/26 and ACH $5,940.00 on 06/30. | D7: Trace the use of funds, document it as legitimate (claim number, loss date, contractor and equipment payments) and exclude it from the suspicious total. Acknowledge it as a mitigating fact or omit it; never present it as a source of the wires.
A8: 4 | B8: Returned wire: the 07/09/2026 wire of $27,835.60 to 'Golden Kestral General Trading FZE' (misspelled) was returned on 07/14/2026 as $27,793.10 (net of $42.50 charges) and re-sent on 07/15/2026. | C8: Transactions tab, account 5523018846120, Group 4 rows on 07/09/2026 (debit) and 07/14/2026 (credit); re-send in Group 2 on 07/15/2026. | D8: Pair the debit and the return credit even though the amounts differ by $42.50, exclude both legs, and count the completed 07/15 wire once. Counting both wires overstates the total by $27,835.60; treating the return as new incoming foreign funds misstates the funds flow.

Sheet Instructor – Group Legend
A1: INSTRUCTOR ONLY – not for distribution to trainees
A2: Group Legend – what each Transactions 'Group' tag represents
A3: Counts and totals are live formulas over the Transactions tab.
A4: Group | B4: What it represents | C4: # Transactions | D4: Total Credits | E4: Total Debits | F4: Total (Credits + Debits)
A5: Group 1 | B5: SUSPICIOUS - Structured cash: in-person teller cash deposits of $8,000-$9,999 to the business and personal accounts, made by the owner and the store manager at four branches, on consecutive days or split between branches on the same day. HNB aggregated the 06/08 and 07/27 same-day pairs and filed CTRs. | C5: =SUMPRODUCT((LEN(Transactions!$B$2:$B$111)>0)*(Transactions!$J$2:$J$111="Group 1")) -> 16 | D5: =SUMPRODUCT((LEN(Transactions!$B$2:$B$111)>0)*(Transactions!$J$2:$J$111="Group 1")*(Transactions!$I$2:$I$111="C")*Transactions!$F$2:$F$111) -> 148150 | E5: =SUMPRODUCT((LEN(Transactions!$B$2:$B$111)>0)*(Transactions!$J$2:$J$111="Group 1")*(Transactions!$I$2:$I$111="D")*Transactions!$G$2:$G$111) -> 0 | F5: =D5+E5 -> 148150
A6: Group 2 | B6: SUSPICIOUS - Completed outgoing international wires (USD) to Golden Kestrel General Trading FZE (Dunecrest Commercial Bank PJSC, Dubai, UAE); vague memos ('inventory', 'consulting'). Excludes the returned 07/09 wire (Group 4). | C6: =SUMPRODUCT((LEN(Transactions!$B$2:$B$111)>0)*(Transactions!$J$2:$J$111="Group 2")) -> 4 | D6: =SUMPRODUCT((LEN(Transactions!$B$2:$B$111)>0)*(Transactions!$J$2:$J$111="Group 2")*(Transactions!$I$2:$I$111="C")*Transactions!$F$2:$F$111) -> 0 | E6: =SUMPRODUCT((LEN(Transactions!$B$2:$B$111)>0)*(Transactions!$J$2:$J$111="Group 2")*(Transactions!$I$2:$I$111="D")*Transactions!$G$2:$G$111) -> 98544.45 | F6: =D6+E6 -> 98544.45
A7: Group 3 | B7: SUSPICIOUS - Outgoing domestic wires to Stonebridge Crest Holdings LLC (Lakemont Federal Bank); beneficiary address matches the owner's residence. Two from the business account, one from the personal account. | C7: =SUMPRODUCT((LEN(Transactions!$B$2:$B$111)>0)*(Transactions!$J$2:$J$111="Group 3")) -> 3 | D7: =SUMPRODUCT((LEN(Transactions!$B$2:$B$111)>0)*(Transactions!$J$2:$J$111="Group 3")*(Transactions!$I$2:$I$111="C")*Transactions!$F$2:$F$111) -> 0 | E7: =SUMPRODUCT((LEN(Transactions!$B$2:$B$111)>0)*(Transactions!$J$2:$J$111="Group 3")*(Transactions!$I$2:$I$111="D")*Transactions!$G$2:$G$111) -> 41500 | F7: =D7+E7 -> 41500
A8: Group 4 | B8: EXCLUDED - Returned wire pair: 07/09 wire to a misspelled beneficiary ('Golden Kestral...') and its 07/14 return credit (less a correspondent charge). The funds were re-sent on 07/15 (counted in Group 2). | C8: =SUMPRODUCT((LEN(Transactions!$B$2:$B$111)>0)*(Transactions!$J$2:$J$111="Group 4")) -> 2 | D8: =SUMPRODUCT((LEN(Transactions!$B$2:$B$111)>0)*(Transactions!$J$2:$J$111="Group 4")*(Transactions!$I$2:$I$111="C")*Transactions!$F$2:$F$111) -> 27793.1 | E8: =SUMPRODUCT((LEN(Transactions!$B$2:$B$111)>0)*(Transactions!$J$2:$J$111="Group 4")*(Transactions!$I$2:$I$111="D")*Transactions!$G$2:$G$111) -> 27835.6 | F8: =D8+E8 -> 55628.7
A9: Group 5 | B9: EXCLUDED (context; acceptable alternative to include) - Single cash deposit above $10,000 on 05/05; CTR filed. Shows awareness of the reporting threshold; every later single deposit is below $10,000. | C9: =SUMPRODUCT((LEN(Transactions!$B$2:$B$111)>0)*(Transactions!$J$2:$J$111="Group 5")) -> 1 | D9: =SUMPRODUCT((LEN(Transactions!$B$2:$B$111)>0)*(Transactions!$J$2:$J$111="Group 5")*(Transactions!$I$2:$I$111="C")*Transactions!$F$2:$F$111) -> 11240 | E9: =SUMPRODUCT((LEN(Transactions!$B$2:$B$111)>0)*(Transactions!$J$2:$J$111="Group 5")*(Transactions!$I$2:$I$111="D")*Transactions!$G$2:$G$111) -> 0 | F9: =D9+E9 -> 11240
A10: Group 6 | B10: EXCLUDED - Legitimate: insurance claim proceeds (06/22) and their documented use (repair contractor check and equipment ACH). | C10: =SUMPRODUCT((LEN(Transactions!$B$2:$B$111)>0)*(Transactions!$J$2:$J$111="Group 6")) -> 3 | D10: =SUMPRODUCT((LEN(Transactions!$B$2:$B$111)>0)*(Transactions!$J$2:$J$111="Group 6")*(Transactions!$I$2:$I$111="C")*Transactions!$F$2:$F$111) -> 18650 | E10: =SUMPRODUCT((LEN(Transactions!$B$2:$B$111)>0)*(Transactions!$J$2:$J$111="Group 6")*(Transactions!$I$2:$I$111="D")*Transactions!$G$2:$G$111) -> 17740 | F10: =D10+E10 -> 36390
A11: Group 7 | B11: MITIGATING - Weekly merchant card settlements from Cardline Merchant Services; consistent with KYC expected card volume. | C11: =SUMPRODUCT((LEN(Transactions!$B$2:$B$111)>0)*(Transactions!$J$2:$J$111="Group 7")) -> 18 | D11: =SUMPRODUCT((LEN(Transactions!$B$2:$B$111)>0)*(Transactions!$J$2:$J$111="Group 7")*(Transactions!$I$2:$I$111="C")*Transactions!$F$2:$F$111) -> 96728.59 | E11: =SUMPRODUCT((LEN(Transactions!$B$2:$B$111)>0)*(Transactions!$J$2:$J$111="Group 7")*(Transactions!$I$2:$I$111="D")*Transactions!$G$2:$G$111) -> 0 | F11: =D11+E11 -> 96728.59
A12: Group 8 | B12: MITIGATING - Routine night-depository cash deposits of store receipts; consistent with KYC expected cash. | C12: =SUMPRODUCT((LEN(Transactions!$B$2:$B$111)>0)*(Transactions!$J$2:$J$111="Group 8")) -> 8 | D12: =SUMPRODUCT((LEN(Transactions!$B$2:$B$111)>0)*(Transactions!$J$2:$J$111="Group 8")*(Transactions!$I$2:$I$111="C")*Transactions!$F$2:$F$111) -> 9812.25 | E12: =SUMPRODUCT((LEN(Transactions!$B$2:$B$111)>0)*(Transactions!$J$2:$J$111="Group 8")*(Transactions!$I$2:$I$111="D")*Transactions!$G$2:$G$111) -> 0 | F12: =D12+E12 -> 9812.25
A13: Group 9 | B13: MITIGATING - Operating expenses: rent, payroll, established parts supplier (MobileSource) and utilities, paid by ACH. | C13: =SUMPRODUCT((LEN(Transactions!$B$2:$B$111)>0)*(Transactions!$J$2:$J$111="Group 9")) -> 25 | D13: =SUMPRODUCT((LEN(Transactions!$B$2:$B$111)>0)*(Transactions!$J$2:$J$111="Group 9")*(Transactions!$I$2:$I$111="C")*Transactions!$F$2:$F$111) -> 0 | E13: =SUMPRODUCT((LEN(Transactions!$B$2:$B$111)>0)*(Transactions!$J$2:$J$111="Group 9")*(Transactions!$I$2:$I$111="D")*Transactions!$G$2:$G$111) -> 90883.54 | F13: =D13+E13 -> 90883.54
